<?xml version="1.0"?>
<robot name="x-t03">
    <link name="base_link">
        <visual>
            <origin rpy="0 0 0" xyz="0 0 0.65"/>
            <geometry>
                <box size="0.7 .6 1.2"/>
            </geometry>            
            <material name="gray">
                <color rgba="0.7 0.7 .7 0.85"/>
            </material>
        </visual>
    </link>

    <joint name="right_wheel_joint" type="continuous">
        <origin rpy="0 0 0" xyz="0 -0.26 0.1"/>
        <parent link="base_link"/>
        <child link="right_wheel"/>
        <axis xyz="0 1 0"/>
    </joint>

    <link name="right_wheel">
        <visual>
            <origin xyz="0 0 0" rpy="1.5707 0 0" />
            <geometry>
                <cylinder length=".04" radius="0.1"/>
            </geometry>
            <material name="black">
                <color rgba="0 0 0 1"/>
            </material>
        </visual>
    </link>

    <joint name="left_wheel_joint" type="continuous">
        <origin rpy="0 0 0" xyz="0 0.26 0.1"/>
        <parent link="base_link"/>
        <child link="left_wheel"/>
        <axis xyz="0 1 0"/>
    </joint>

    <link name="left_wheel">
        <visual>
            <origin xyz="0 0 0" rpy="1.5707 0 0" />
            <geometry>
                <cylinder length=".04" radius="0.1"/>
            </geometry>
            <material name="black">
                <color rgba="0 0 0 1"/>
            </material>
        </visual>
    </link>

    <joint name="camera_link_joint" type="continuous">
        <origin rpy="0 0 0" xyz="0.3 0 1.25"/>
        <parent link="base_link"/>
        <child link="camera_link"/>
        <axis xyz="0 1 0"/>
    </joint>

    <link name="camera_link">
        <visual>
            <origin xyz="0 0 0" rpy="0 0 0" />
            <geometry>
                <cylinder length=".02" radius="0.03"/>
            </geometry>
            <material name="white">
                <color rgba="1 1 1 1"/>
            </material>
        </visual>
    </link>
</robot>